Workbook

Sheet riepilogo
A1: Controllo qualità — PR 19, con le righe riaperte dalla PR 20
A2: Il CSV in docs/ resta la fonte versionata. Questo foglio è la vista di lavoro: si compila qui, poi si rifonde nel CSV.
A4: Come si compila
A5: · Si lavora nel foglio «da fare», un dispositivo alla volta: il filtro in testa alla colonna serve a quello.
A6: · Una riga è una azione sola, su un dispositivo solo, contro un componente solo. Se serve fare altro per rispondere, la riga è scritta male: dillo.
A7: · Nella colonna ESITO il menu propone OK · No · OK, ma · N.A. — ma si può scrivere quello che si vuole, il menu non blocca niente.
A8: · Se non è OK, in DIFETTO OSSERVATO basta una frase: che cosa si è visto. La diagnosi viene dopo.
A9: · La colonna «verifica automatica» porta la misura già presa dal browser, dove c’è. Se contraddice quello che vedi, vince quello che vedi.
A11: Quanto manca, per dispositivo
A12: Dispositivo | B12: Da fare | C12: di cui alta | D12: Fatte | E12: Totale
A13: iPhone Safari 15.4-16.3 | B13: =COUNTIFS(tutte!C:C,A13,tutte!I:I,"") | C13: =COUNTIFS(tutte!C:C,A13,tutte!I:I,"",tutte!B:B,"alta") | D13: =COUNTIFS(tutte!C:C,A13,tutte!I:I,"<>") | E13: =COUNTIF(tutte!C:C,A13)
A14: iPhone recente (Safari 18+) | B14: =COUNTIFS(tutte!C:C,A14,tutte!I:I,"") | C14: =COUNTIFS(tutte!C:C,A14,tutte!I:I,"",tutte!B:B,"alta") | D14: =COUNTIFS(tutte!C:C,A14,tutte!I:I,"<>") | E14: =COUNTIF(tutte!C:C,A14)
A15: Android Chrome recente | B15: =COUNTIFS(tutte!C:C,A15,tutte!I:I,"") | C15: =COUNTIFS(tutte!C:C,A15,tutte!I:I,"",tutte!B:B,"alta") | D15: =COUNTIFS(tutte!C:C,A15,tutte!I:I,"<>") | E15: =COUNTIF(tutte!C:C,A15)
A16: Android di 4 anni (Chrome) | B16: =COUNTIFS(tutte!C:C,A16,tutte!I:I,"") | C16: =COUNTIFS(tutte!C:C,A16,tutte!I:I,"",tutte!B:B,"alta") | D16: =COUNTIFS(tutte!C:C,A16,tutte!I:I,"<>") | E16: =COUNTIF(tutte!C:C,A16)
A17: iPad (Safari) | B17: =COUNTIFS(tutte!C:C,A17,tutte!I:I,"") | C17: =COUNTIFS(tutte!C:C,A17,tutte!I:I,"",tutte!B:B,"alta") | D17: =COUNTIFS(tutte!C:C,A17,tutte!I:I,"<>") | E17: =COUNTIF(tutte!C:C,A17)
A18: Desktop Chrome (Windows) | B18: =COUNTIFS(tutte!C:C,A18,tutte!I:I,"") | C18: =COUNTIFS(tutte!C:C,A18,tutte!I:I,"",tutte!B:B,"alta") | D18: =COUNTIFS(tutte!C:C,A18,tutte!I:I,"<>") | E18: =COUNTIF(tutte!C:C,A18)
A19: Desktop Firefox (Windows) | B19: =COUNTIFS(tutte!C:C,A19,tutte!I:I,"") | C19: =COUNTIFS(tutte!C:C,A19,tutte!I:I,"",tutte!B:B,"alta") | D19: =COUNTIFS(tutte!C:C,A19,tutte!I:I,"<>") | E19: =COUNTIF(tutte!C:C,A19)
A20: Desktop Safari (macOS) | B20: =COUNTIFS(tutte!C:C,A20,tutte!I:I,"") | C20: =COUNTIFS(tutte!C:C,A20,tutte!I:I,"",tutte!B:B,"alta") | D20: =COUNTIFS(tutte!C:C,A20,tutte!I:I,"<>") | E20: =COUNTIF(tutte!C:C,A20)
A21: Totale | B21: =SUM(B13:B20) | C21: =SUM(C13:C20) | D21: =SUM(D13:D20) | E21: =SUM(E13:E20)
A23: Che cosa non può fare nessuna automazione
A24: · Un telefono vero: l’emulazione ha già mancato un difetto vero alla PR 18 — la fotografia che copriva il titolo.
A25: · Safari: nessun WebKit su questa macchina.
A26: · Uno screen reader: VoiceOver e NVDA vanno sentiti.
A27: · Il fuoco: :focus e :focus-visible non si applicano quando la finestra non è in primo piano, e questo vale per ogni strumento.
A28: · Il CMS: serve l’accesso, e ogni prova scrive davvero sul repository.

Sheet da fare
A1: ID | B1: Priorità | C1: Dispositivo | D1: Contesto | E1: Rotta | F1: Componente | G1: Azione | H1: Esito atteso | I1: Esito | J1: Difetto osservato | K1: Area | L1: Riferimento | M1: Verifica automatica
A2: QA-001 | B2: alta | C2: iPhone Safari 15.4-16.3 | D2: verticale | E2: / | F2: Programme | G2: Aprire l’indirizzo e guardare cosa è a schermo | H2: Si apre sulla serata 81, la prima futura non annullata, non in cima all’archivio | K2: Resa sul dispositivo | L2: regola 10
A3: QA-002 | B3: alta | C3: iPhone Safari 15.4-16.3 | D3: verticale | E3: / | F3: Programme | G3: Un flick verso l’alto | H3: Lo snap aggancia la serata 82 intera; non resta a metà fra due scene | K3: Resa sul dispositivo | L3: regola 1
A4: QA-003 | B4: media | C4: iPhone Safari 15.4-16.3 | D4: verticale | E4: / | F4: Programme | G4: Trascinare lentamente fino a metà scena e rilasciare | H4: Atterra su una sola scena e non oscilla fra le due | K4: Resa sul dispositivo | L4: regola 1
A5: QA-004 | B5: alta | C5: iPhone Safari 15.4-16.3 | D5: verticale | E5: /81 | F5: Scene | G5: Leggere il titolo della serata | H5: Intero, non tagliato dal bordo né coperto dalla pillola della navigazione | K5: Resa sul dispositivo | L5: PR 18
A6: QA-005 | B6: alta | C6: iPhone Safari 15.4-16.3 | D6: verticale | E6: /81 | F6: Scene | G6: Guardare la fotografia | H6: La capsula inclinata sta nella sua fascia e non copre titolo né occhiello | K6: Resa sul dispositivo | L6: PR 18
A7: QA-006 | B7: media | C7: iPhone Safari 15.4-16.3 | D7: verticale | E7: /81 | F7: Scene | G7: Leggere la riga della sede | H7: Nome del luogo sopra, via e città sotto, su due righe distinte | K7: Resa sul dispositivo | L7: regola 19
A8: QA-007 | B8: alta | C8: iPhone Safari 15.4-16.3 | D8: verticale | E8: /81 | F8: Scene | G8: Leggere la nota sotto i bottoni | H8: Leggibile per intero, non tagliata dalla barra della Timeline | K8: Resa sul dispositivo | L8: PR 18
A9: QA-008 | B9: alta | C9: iPhone Safari 15.4-16.3 | D9: verticale | E9: /80 | F9: Scene | G9: Guardare la serata annullata | H9: Titolo e data barrati, la parola «annullata» leggibile sopra il titolo | K9: Resa sul dispositivo | L9: PR 3
A10: QA-009 | B10: media | C10: iPhone Safari 15.4-16.3 | D10: verticale | E10: /78 | F10: Scene | G10: Guardare la descrizione su schermo corto | H10: La descrizione cede prima della fotografia, che resta sempre | K10: Resa sul dispositivo | L10: PR 18
A11: QA-010 | B11: alta | C11: iPhone Safari 15.4-16.3 | D11: verticale | E11: /81 | F11: Button | G11: Toccare «Prenota il posto» | H11: Si apre il modale con la spiegazione, non direttamente WhatsApp | K11: Resa sul dispositivo | L11: PR 12
A12: QA-011 | B12: alta | C12: iPhone Safari 15.4-16.3 | D12: verticale | E12: /81 | F12: Modal | G12: Leggere il pannello aperto | H12: Il testo sta dentro il pannello; se è lungo scorre il pannello e non la pagina | K12: Resa sul dispositivo | L12: vincoli-tecnici
A13: QA-012 | B13: alta | C13: iPhone Safari 15.4-16.3 | D13: verticale | E13: /81 | F13: Modal | G13: Toccare la X di chiusura | H13: Si chiude e la pagina è rimasta sulla serata 81 | K13: Resa sul dispositivo | L13: PR 12
... A50: QA-054 | B50: alta | C50: Android Chrome recente | D50: verticale | E50: / | F50: Timeline | G50: Scorrere la barra fino alla 78 e toccarla | H50: La barra si muove fino a portare la pillola al centro e la pagina arriva sulla 78 | K50: Resa sul dispositivo | L50: regola 14
A51: QA-064 | B51: alta | C51: Android di 4 anni (Chrome) | D51: verticale | E51: / | F51: Timeline | G51: Scorrere la barra fino alla 78 e toccarla | H51: La barra si muove fino a portare la pillola al centro e la pagina arriva sulla 78 | K51: Resa sul dispositivo | L51: regola 14 | M51: Provata su un Google Pixel (modello da registrare).
A52: QA-069 | B52: alta | C52: iPhone Safari 15.4-16.3 | D52: verticale | E52: / | F52: Programme | G52: Guardare se il layout è quello del telefono o quello del desktop | H52: Layout a una colonna: le media query si applicano, quindi il minificatore non ha riscritto la sintassi range | K52: Soglia dei browser | L52: checkMediaRangeSyntax
A53: QA-070 | B53: alta | C53: iPhone Safari 15.4-16.3 | D53: verticale | E53: / | F53: Programme | G53: Scorrere con la barra di Safari mostrata e poi ritratta | H53: La scena resta alta quanto lo schermo e le posizioni di snap non saltano (svh, non dvh) | K53: Soglia dei browser | L53: regola 5
A54: QA-071 | B54: alta | C54: iPhone Safari 15.4-16.3 | D54: verticale | E54: /81 | F54: Modal | G54: Toccare «Prenota il posto» | H54: Il modale si apre; se <dialog> non c’è, al suo posto compare il link diretto e non un bottone morto | K54: Soglia dei browser | L54: PR 12
A55: QA-072 | B55: media | C55: iPhone Safari 15.4-16.3 | D55: verticale | E55: / | F55: Timeline | G55: Guardare lo sfondo della barra in basso | H55: La barra è velata e leggibile: il -webkit-backdrop-filter è quello che risponde qui | K55: Soglia dei browser | L55: Timeline.astro
A56: QA-073 | B56: media | C56: iPhone Safari 15.4-16.3 | D56: verticale | E56: / | F56: Scene | G56: Scorrere venti serate di seguito | H56: Nessuno scatto: senza content-visibility la pagina resta comunque fluida | K56: Soglia dei browser | L56: Scene.astro
A57: QA-074 | B57: media | C57: iPhone Safari 15.4-16.3 | D57: verticale | E57: /81 | F57: Scene | G57: Guardare la descrizione tagliata a tre righe | H57: Il taglio funziona e non lascia una riga a metà | K57: Soglia dei browser | L57: Scene.astro
A58: QA-076 | B58: alta | C58: iPhone recente (Safari 18+) | D58: orizzontale | E58: /81 | F58: Scene | G58: Ruotare il telefono e guardare la scena | H58: Titolo, data, sede, bottoni e nota sono tutti a schermo | K58: Orizzontale su telefono | L58: piano PR 19
A59: QA-077 | B59: alta | C59: iPhone recente (Safari 18+) | D59: orizzontale | E59: /81 | F59: Scene | G59: Guardare la fotografia in orizzontale | H59: La foto non schiaccia il testo né esce dalla sua fascia | K59: Orizzontale su telefono | L59: piano PR 19
A60: QA-078 | B60: alta | C60: iPhone recente (Safari 18+) | D60: orizzontale | E60: / | F60: Timeline | G60: Guardare la barra in basso in orizzontale | H60: La barra non copre la nota né i bottoni della scena | K60: Orizzontale su telefono | L60: piano PR 19
A61: QA-079 | B61: alta | C61: iPhone recente (Safari 18+) | D61: orizzontale | E61: / | F61: SiteNav | G61: Guardare la pillola in alto in orizzontale | H61: Non copre il titolo della serata | K61: Orizzontale su telefono | L61: piano PR 19
A62: QA-080 | B62: media | C62: iPhone recente (Safari 18+) | D62: orizzontale | E62: /78 | F62: Scene | G62: Guardare la serata con i materiali in orizzontale | H62: Il bottone «Rivedi la serata» è raggiungibile senza scorrere la scena | K62: Orizzontale su telefono | L62: vincoli-tecnici
A63: QA-081 | B63: media | C63: iPhone recente (Safari 18+) | D63: orizzontale | E63: /81 | F63: Modal | G63: Aprire il modale in orizzontale | H63: Il pannello sta nello schermo e la X non finisce fuori dal bordo | K63: Orizzontale su telefono | L63: Modal.astro
... A65: QA-083 | B65: media | C65: iPhone recente (Safari 18+) | D65: orizzontale | E65: / | F65: Programme | G65: Ruotare mentre si è sulla serata 82 | H65: Dopo la rotazione si è ancora sulla 82 e non su un’altra | K65: Orizzontale su telefono | L65: regola 1
A66: QA-098 | B66: alta | C66: Desktop Chrome (Windows) | D66: 1280x800 | E66: / | F66: Timeline | G66: Cliccare la tacca della serata 78 | H66: La pagina si muove fino alla 78 e ci si ferma: rotaia, accento e indirizzo dicono tutti la 78 | J66: Diventa /78#serata-78 | K66: Resa sul desktop | L66: regola 16
A67: QA-099 | B67: alta | C67: Desktop Chrome (Windows) | D67: 1280x800 | E67: / | F67: Timeline | G67: Cliccare due tacche lontane a due decimi di distanza | H67: Atterra sulla seconda; rotaia, accento e indirizzo dicono la stessa serata | J67: Manca l'animazione dello scorrimento | K67: Resa sul desktop | L67: regola 15
A68: QA-115 | B68: alta | C68: Desktop Firefox (Windows) | D68: 1280x800 | E68: / | F68: Timeline | G68: Cliccare la tacca della serata 78 | H68: La pagina si muove fino alla 78 e ci si ferma: rotaia, accento e indirizzo dicono tutti la 78 | K68: Resa sul desktop | L68: regola 16 | M68: Atterra sulla 78, indirizzo /78#serata-78, accento del ciclo 2
A69: QA-116 | B69: alta | C69: Desktop Firefox (Windows) | D69: 1280x800 | E69: / | F69: Timeline | G69: Cliccare due tacche lontane a due decimi di distanza | H69: Atterra sulla seconda; rotaia, accento e indirizzo dicono la stessa serata | K69: Resa sul desktop | L69: regola 15 | M69: Due click a due decimi di distanza: scena 83, indirizzo /83, accento 6, tacca corrente all’indice 4 — le quattro cose concordano
A70: QA-126 | B70: alta | C70: Desktop Safari (macOS) | D70: 1280x800 | E70: / | F70: Programme | G70: Aprire l’indirizzo | H70: Si apre sulla serata 81, già disegnata lì: nessun salto visibile dopo il primo disegno | K70: Resa sul desktop | L70: Programme.astro
A71: QA-127 | B71: alta | C71: Desktop Safari (macOS) | D71: 1280x800 | E71: / | F71: Programme | G71: Un colpo di rotella | H71: Passa a una serata sola e aggancia; la rotella non spinge due scene in una volta | K71: Resa sul desktop | L71: regola 1
A72: QA-128 | B72: alta | C72: Desktop Safari (macOS) | D72: 1280x800 | E72: / | F72: Programme | G72: Uno scorrimento con il trackpad a due dita | H72: Aggancia senza combattere il gesto: nessun rimbalzo fra due scene | K72: Resa sul desktop | L72: regola 1
A73: QA-129 | B73: media | C73: Desktop Safari (macOS) | D73: 1280x800 | E73: / | F73: Programme | G73: Passare la rotella sopra la pillola della navigazione | H73: Il programma scorre lo stesso: la pillola non è una zona morta | K73: Resa sul desktop | L73: SiteNav.astro
A74: QA-130 | B74: media | C74: Desktop Safari (macOS) | D74: 1280x800 | E74: / | F74: Programme | G74: Passare la rotella sopra la rotaia della Timeline | H74: Il programma scorre lo stesso | K74: Resa sul desktop | L74: Timeline.astro
A75: QA-131 | B75: alta | C75: Desktop Safari (macOS) | D75: 1280x800 | E75: / | F75: Timeline | G75: Guardare la rotaia a destra | H75: Tutte le serate hanno una tacca; le vicine portano la data, le lontane sono segni | K75: Resa sul desktop | L75: regola 14
A76: QA-132 | B76: alta | C76: Desktop Safari (macOS) | D76: 1280x800 | E76: / | F76: Timeline | G76: Cliccare la tacca della serata 78 | H76: La pagina si muove fino alla 78 e ci si ferma: rotaia, accento e indirizzo dicono tutti la 78 | K76: Resa sul desktop | L76: regola 16
A77: QA-133 | B77: alta | C77: Desktop Safari (macOS) | D77: 1280x800 | E77: / | F77: Timeline | G77: Cliccare due tacche lontane a due decimi di distanza | H77: Atterra sulla seconda; rotaia, accento e indirizzo dicono la stessa serata | K77: Resa sul desktop | L77: regola 15
...

Sheet tutte
A1: ID | B1: Priorità | C1: Dispositivo | D1: Contesto | E1: Rotta | F1: Componente | G1: Azione | H1: Esito atteso | I1: Esito | J1: Difetto osservato | K1: Area | L1: Riferimento | M1: Verifica automatica
A2: QA-001 | B2: alta | C2: iPhone Safari 15.4-16.3 | D2: verticale | E2: / | F2: Programme | G2: Aprire l’indirizzo e guardare cosa è a schermo | H2: Si apre sulla serata 81, la prima futura non annullata, non in cima all’archivio | K2: Resa sul dispositivo | L2: regola 10
A3: QA-002 | B3: alta | C3: iPhone Safari 15.4-16.3 | D3: verticale | E3: / | F3: Programme | G3: Un flick verso l’alto | H3: Lo snap aggancia la serata 82 intera; non resta a metà fra due scene | K3: Resa sul dispositivo | L3: regola 1
A4: QA-003 | B4: media | C4: iPhone Safari 15.4-16.3 | D4: verticale | E4: / | F4: Programme | G4: Trascinare lentamente fino a metà scena e rilasciare | H4: Atterra su una sola scena e non oscilla fra le due | K4: Resa sul dispositivo | L4: regola 1
A5: QA-004 | B5: alta | C5: iPhone Safari 15.4-16.3 | D5: verticale | E5: /81 | F5: Scene | G5: Leggere il titolo della serata | H5: Intero, non tagliato dal bordo né coperto dalla pillola della navigazione | K5: Resa sul dispositivo | L5: PR 18
A6: QA-005 | B6: alta | C6: iPhone Safari 15.4-16.3 | D6: verticale | E6: /81 | F6: Scene | G6: Guardare la fotografia | H6: La capsula inclinata sta nella sua fascia e non copre titolo né occhiello | K6: Resa sul dispositivo | L6: PR 18
A7: QA-006 | B7: media | C7: iPhone Safari 15.4-16.3 | D7: verticale | E7: /81 | F7: Scene | G7: Leggere la riga della sede | H7: Nome del luogo sopra, via e città sotto, su due righe distinte | K7: Resa sul dispositivo | L7: regola 19
A8: QA-007 | B8: alta | C8: iPhone Safari 15.4-16.3 | D8: verticale | E8: /81 | F8: Scene | G8: Leggere la nota sotto i bottoni | H8: Leggibile per intero, non tagliata dalla barra della Timeline | K8: Resa sul dispositivo | L8: PR 18
A9: QA-008 | B9: alta | C9: iPhone Safari 15.4-16.3 | D9: verticale | E9: /80 | F9: Scene | G9: Guardare la serata annullata | H9: Titolo e data barrati, la parola «annullata» leggibile sopra il titolo | K9: Resa sul dispositivo | L9: PR 3
A10: QA-009 | B10: media | C10: iPhone Safari 15.4-16.3 | D10: verticale | E10: /78 | F10: Scene | G10: Guardare la descrizione su schermo corto | H10: La descrizione cede prima della fotografia, che resta sempre | K10: Resa sul dispositivo | L10: PR 18
A11: QA-010 | B11: alta | C11: iPhone Safari 15.4-16.3 | D11: verticale | E11: /81 | F11: Button | G11: Toccare «Prenota il posto» | H11: Si apre il modale con la spiegazione, non direttamente WhatsApp | K11: Resa sul dispositivo | L11: PR 12
A12: QA-011 | B12: alta | C12: iPhone Safari 15.4-16.3 | D12: verticale | E12: /81 | F12: Modal | G12: Leggere il pannello aperto | H12: Il testo sta dentro il pannello; se è lungo scorre il pannello e non la pagina | K12: Resa sul dispositivo | L12: vincoli-tecnici
A13: QA-012 | B13: alta | C13: iPhone Safari 15.4-16.3 | D13: verticale | E13: /81 | F13: Modal | G13: Toccare la X di chiusura | H13: Si chiude e la pagina è rimasta sulla serata 81 | K13: Resa sul dispositivo | L13: PR 12
... A49: QA-048 | B49: media | C49: iPhone recente (Safari 18+) | D49: verticale | E49: / | F49: Base | G49: Guardare la linguetta e la barra del browser | H49: La favicon si legge; la barra è colorata come il sito (theme-color) | K49: Resa sul dispositivo | L49: PR 19
A50: QA-049 | B50: alta | C50: Android Chrome recente | D50: verticale | E50: / | F50: Programme | G50: Aprire l’indirizzo e guardare cosa è a schermo | H50: Si apre sulla serata 81, non in cima all’archivio | I50: OK | K50: Resa sul dispositivo | L50: regola 10
A51: QA-050 | B51: alta | C51: Android Chrome recente | D51: verticale | E51: / | F51: Programme | G51: Un flick verso l’alto | H51: Lo snap aggancia la serata intera | I51: OK | K51: Resa sul dispositivo | L51: regola 1
A52: QA-051 | B52: alta | C52: Android Chrome recente | D52: verticale | E52: /81 | F52: Scene | G52: Guardare titolo, foto e nota insieme | H52: Nessuno dei tre è tagliato o coperto | I52: OK | K52: Resa sul dispositivo | L52: PR 18
A53: QA-052 | B53: alta | C53: Android Chrome recente | D53: verticale | E53: /81 | F53: Button | G53: Toccare «Prenota il posto» | H53: Si apre il modale | I53: OK | K53: Resa sul dispositivo | L53: PR 12
A54: QA-053 | B54: alta | C54: Android Chrome recente | D54: verticale | E54: /81 | F54: Modal | G54: Chiudere con la X | H54: Si chiude e la pagina resta sulla serata 81 | I54: OK | K54: Resa sul dispositivo | L54: PR 12
A55: QA-054 | B55: alta | C55: Android Chrome recente | D55: verticale | E55: / | F55: Timeline | G55: Scorrere la barra fino alla 78 e toccarla | H55: La barra si muove fino a portare la pillola al centro e la pagina arriva sulla 78 | K55: Resa sul dispositivo | L55: regola 14
A56: QA-055 | B56: media | C56: Android Chrome recente | D56: verticale | E56: / | F56: SiteNav | G56: Aprire la tendina | H56: Si apre e mostra le quattro voci | I56: OK | K56: Resa sul dispositivo | L56: regola 18
A57: QA-056 | B57: alta | C57: Android Chrome recente | D57: verticale | E57: / | F57: SiteNav | G57: Leggere il marchio | H57: «in Periferia» c’è per intero | I57: OK | K57: Resa sul dispositivo | L57: regola 7
A58: QA-057 | B58: media | C58: Android Chrome recente | D58: verticale | E58: /chi-siamo | F58: pages.css | G58: Scorrere la pagina fino in fondo | H58: Nessuno scorrimento orizzontale, nessun blocco tagliato | I58: OK | K58: Resa sul dispositivo | L58: PR 13
A59: QA-058 | B59: media | C59: Android Chrome recente | D59: verticale | E59: /78 | F59: Scene | G59: Aprire «Rivedi la serata» | H59: Il pannello porta le righe dei materiali | I59: OK | K59: Resa sul dispositivo | L59: PR 12
A60: QA-059 | B60: alta | C60: Android di 4 anni (Chrome) | D60: verticale | E60: / | F60: Programme | G60: Aprire l’indirizzo e guardare cosa è a schermo | H60: Si apre sulla serata 81, non in cima all’archivio | I60: OK | K60: Resa sul dispositivo | L60: regola 10 | M60: Provata su un Google Pixel (modello da registrare).
A61: QA-060 | B61: alta | C61: Android di 4 anni (Chrome) | D61: verticale | E61: / | F61: Programme | G61: Un flick verso l’alto | H61: Lo snap aggancia la serata intera | I61: OK | K61: Resa sul dispositivo | L61: regola 1 | M61: Provata su un Google Pixel (modello da registrare).
A62: QA-061 | B62: alta | C62: Android di 4 anni (Chrome) | D62: verticale | E62: /81 | F62: Scene | G62: Guardare titolo, foto e nota insieme | H62: Nessuno dei tre è tagliato o coperto | I62: OK | K62: Resa sul dispositivo | L62: PR 18 | M62: Provata su un Google Pixel (modello da registrare).
A63: QA-062 | B63: alta | C63: Android di 4 anni (Chrome) | D63: verticale | E63: /81 | F63: Button | G63: Toccare «Prenota il posto» | H63: Si apre il modale | I63: OK | K63: Resa sul dispositivo | L63: PR 12 | M63: Provata su un Google Pixel (modello da registrare).
A64: QA-063 | B64: alta | C64: Android di 4 anni (Chrome) | D64: verticale | E64: /81 | F64: Modal | G64: Chiudere con la X | H64: Si chiude e la pagina resta sulla serata 81 | I64: OK | K64: Resa sul dispositivo | L64: PR 12 | M64: Provata su un Google Pixel (modello da registrare).
A65: QA-064 | B65: alta | C65: Android di 4 anni (Chrome) | D65: verticale | E65: / | F65: Timeline | G65: Scorrere la barra fino alla 78 e toccarla | H65: La barra si muove fino a portare la pillola al centro e la pagina arriva sulla 78 | K65: Resa sul dispositivo | L65: regola 14 | M65: Provata su un Google Pixel (modello da registrare).
A66: QA-065 | B66: media | C66: Android di 4 anni (Chrome) | D66: verticale | E66: / | F66: SiteNav | G66: Aprire la tendina | H66: Si apre e mostra le quattro voci | I66: OK | K66: Resa sul dispositivo | L66: regola 18 | M66: Provata su un Google Pixel (modello da registrare).
A67: QA-066 | B67: alta | C67: Android di 4 anni (Chrome) | D67: verticale | E67: / | F67: SiteNav | G67: Leggere il marchio | H67: «in Periferia» c’è per intero | I67: OK | K67: Resa sul dispositivo | L67: regola 7 | M67: Provata su un Google Pixel (modello da registrare).
A68: QA-067 | B68: media | C68: Android di 4 anni (Chrome) | D68: verticale | E68: /chi-siamo | F68: pages.css | G68: Scorrere la pagina fino in fondo | H68: Nessuno scorrimento orizzontale, nessun blocco tagliato | I68: OK | K68: Resa sul dispositivo | L68: PR 13 | M68: Provata su un Google Pixel (modello da registrare).
A69: QA-068 | B69: media | C69: Android di 4 anni (Chrome) | D69: verticale | E69: /78 | F69: Scene | G69: Aprire «Rivedi la serata» | H69: Il pannello porta le righe dei materiali | I69: OK | K69: Resa sul dispositivo | L69: PR 12 | M69: Provata su un Google Pixel (modello da registrare).
A70: QA-069 | B70: alta | C70: iPhone Safari 15.4-16.3 | D70: verticale | E70: / | F70: Programme | G70: Guardare se il layout è quello del telefono o quello del desktop | H70: Layout a una colonna: le media query si applicano, quindi il minificatore non ha riscritto la sintassi range | K70: Soglia dei browser | L70: checkMediaRangeSyntax
A71: QA-070 | B71: alta | C71: iPhone Safari 15.4-16.3 | D71: verticale | E71: / | F71: Programme | G71: Scorrere con la barra di Safari mostrata e poi ritratta | H71: La scena resta alta quanto lo schermo e le posizioni di snap non saltano (svh, non dvh) | K71: Soglia dei browser | L71: regola 5
A72: QA-071 | B72: alta | C72: iPhone Safari 15.4-16.3 | D72: verticale | E72: /81 | F72: Modal | G72: Toccare «Prenota il posto» | H72: Il modale si apre; se <dialog> non c’è, al suo posto compare il link diretto e non un bottone morto | K72: Soglia dei browser | L72: PR 12
A73: QA-072 | B73: media | C73: iPhone Safari 15.4-16.3 | D73: verticale | E73: / | F73: Timeline | G73: Guardare lo sfondo della barra in basso | H73: La barra è velata e leggibile: il -webkit-backdrop-filter è quello che risponde qui | K73: Soglia dei browser | L73: Timeline.astro
A74: QA-073 | B74: media | C74: iPhone Safari 15.4-16.3 | D74: verticale | E74: / | F74: Scene | G74: Scorrere venti serate di seguito | H74: Nessuno scatto: senza content-visibility la pagina resta comunque fluida | K74: Soglia dei browser | L74: Scene.astro
A75: QA-074 | B75: media | C75: iPhone Safari 15.4-16.3 | D75: verticale | E75: /81 | F75: Scene | G75: Guardare la descrizione tagliata a tre righe | H75: Il taglio funziona e non lascia una riga a metà | K75: Soglia dei browser | L75: Scene.astro
...

Sheet difetti
A1: # | B1: Da | C1: Difetto | D1: Destino
A2: 1 | B2: QA-318, QA-323 | C2: Il CMS lascia salvare una serata la cui data contraddice il numero: la build si ferma dopo il commit. Riprodotto due volte su due, la seconda da telefono con la serata 85 | D2: fix qui
A3: 2 | B3: QA-150, QA-257 | C3: Il testo esce dalla scena invece di essere ritagliato: sul desktop mancano sia la soglia sulla descrizione sia overflow: hidden. 26 px a 1280×500, 88 px con un titolo lungo | D3: fix qui
A4: 3 | B4: QA-233, QA-338 | C4: Tre usi di --text-muted a 3,50:1, sotto il 4,5 che serve a un testo. La cifra della statistica invece misura 12,14:1 e passa | D4: fix qui
A5: 4 | B5: QA-105, QA-333 | C5: Il primo tocco del tasto indietro cambia solo l’indirizzo e lascia la pagina ferma | D5: PR propria
A6: 5 | B6: QA-084, QA-085, QA-088, QA-089 | C6: In orizzontale la scena ritaglia 173 px: dentro ci sono data, sede, bottoni e nota. La fotografia scende a 51 px | D6: PR propria
A7: 6 | B7: QA-243 | C7: La pillola della Timeline è alta 36 px, mentre --tap-target del sito vale 44 | D7: da decidere
A8: 7 | B8: QA-238 | C8: La cornice della fotografia passa sotto la rotaia: le date delle tacche cadono sopra l’immagine | D8: fix qui
A9: 8 | B9: QA-261 | C9: Sul desktop la colonna della fotografia resta riservata anche quando la serata non ne ha: 420 px vuoti | D9: fix qui
A10: 9 | B10: QA-294 | C10: Placeholder non è nella rassegna dei componenti | D10: fix qui
A11: 10 | B11: QA-292 | C11: GuestRow è mostrato con due tarature di --guest-size senza che la rassegna lo dica | D11: fix qui
A12: 11 | B12: QA-281 | C12: Il titolo della pagina non segue la serata: chi mette un segnalibro salva il titolo | D12: da decidere
... A20: 19 | B20: QA-323, QA-324 | C20: Il CMS scrive i contenuti in una forma diversa da quella dei file scritti a mano: photo con percorso assoluto, e cancelled: false scritto per esteso. Niente si rompe, ma le due mani non scrivono uguale | D20: da decidere
